<?xml version="1.0"?>
<robot xmlns:sensor="http://playerstage.sourceforge.net/gazebo/xmlschema/#sensor"
       xmlns:controller="http://playerstage.sourceforge.net/gazebo/xmlschema/#controller"
       xmlns:interface="http://playerstage.sourceforge.net/gazebo/xmlschema/#interface">

  <include filename="$(find kuka_lwr_description)/defs/util_defs.xml"/>

  <property name="name" value="1"/>
  <property name="arm_velocity_scale_factor" value="right"/>
  <macro name="kuka_lwr_arm_laas">


    <link name="calib_${name}_arm_base_link">
      <visual>
        <origin xyz="0 0 0" rpy="0 0 0"/>
        <geometry>
          <mesh filename="package://kuka_lwr_description/meshes/arm_base.stl"/>
        </geometry>
        <material name="Orange"/>
      </visual>
    </link>


    <joint name="${name}_arm_0_joint" type="revolute">
      <origin xyz="0 0 0.11" rpy="0 0 0"/>
      <axis xyz="0 0 1"/>
      <limit lower="${-170 * M_PI / 180}" upper="${170 * M_PI / 180}"
             effort="204" velocity="${arm_velocity_scale_factor * 110 * M_PI / 180}" />
      <parent link="calib_${name}_arm_base_link"/>
      <child link="${name}_arm_1_link"/>
    </joint>


    <link name="${name}_arm_1_link">
      <visual>
        <origin xyz="0 0 0" rpy="0 0 ${M_PI}"/>
        <geometry>
          <mesh filename="package://kuka_lwr_description/meshes/arm_segment_a.stl"/>
        </geometry>
        <material name="Orange"/>
      </visual>
    </link>


    <joint name="${name}_arm_1_joint" type="revolute">
      <origin xyz="0 0 0.20" rpy="0 0 0"/>
      <axis xyz="0 -1 0"/>
      <limit lower="${-90 * M_PI / 180}" upper="${90 * M_PI / 180}"
             effort="306" velocity="${arm_velocity_scale_factor * 110 * M_PI / 180}" />       
      <parent link="${name}_arm_1_link"/>
      <child link="${name}_arm_2_link"/>
    </joint>

    <link name="${name}_arm_2_link">
      <visual>
        <origin xyz="0 0 0.2" rpy="${M_PI} 0 ${M_PI}"/>
        <geometry>
          <mesh filename="package://kuka_lwr_description/meshes/arm_segment_b.stl"/>
        </geometry>
        <material name="Orange"/>
      </visual>

    </link>


    <joint name="${name}_arm_2_joint" type="revolute">
      <origin xyz="0 0 0.20" rpy="0 0 0"/>
      <axis xyz="0 0 1"/>
      <limit lower="${-170 * M_PI / 180}" upper="${170 * M_PI / 180}"
             effort="204" velocity="${arm_velocity_scale_factor * 130 * M_PI / 180}" />
      <parent link="${name}_arm_2_link"/>
      <child link="${name}_arm_3_link"/>
    </joint>

    <link name="${name}_arm_3_link">
      <visual>
        <origin xyz="0 0 0" rpy="0 0 0"/>
        <geometry>
          <mesh filename="package://kuka_lwr_description/meshes/arm_segment_a.stl"/>
        </geometry>
        <material name="Orange"/>
      </visual>

    </link>

    <joint name="${name}_arm_3_joint" type="revolute">
      <origin xyz="0 0 0.20" rpy="0 0 0"/>
      <axis xyz="0 1 0"/>
      <limit lower="${-120 * M_PI / 180}" upper="${120 * M_PI / 180}"
             effort="306" velocity="${arm_velocity_scale_factor * 130 * M_PI / 180}" />
      <parent link="${name}_arm_3_link"/>
      <child link="${name}_arm_4_link"/>
    </joint>

    <link name="${name}_arm_4_link">
      <visual>
        <origin xyz="0 0 0.2" rpy="0 ${M_PI} ${M_PI}"/>
        <geometry>
          <mesh filename="package://kuka_lwr_description/meshes/arm_segment_b.stl"/>
        </geometry>
        <material name="Orange"/>
      </visual>
    </link>


    <joint name="${name}_arm_4_joint" type="revolute">
      <origin xyz="0 0 0.20" rpy="0 0 0"/>
      <axis xyz="0 0 1"/>
      <limit lower="${-170 * M_PI / 180}" upper="${170 * M_PI / 180}"
             effort="204" velocity="${arm_velocity_scale_factor * 130 * M_PI / 180}" />
      <parent link="${name}_arm_4_link"/>
      <child link="${name}_arm_5_link"/>
    </joint>

    <link name="${name}_arm_5_link">
      <visual>
        <origin xyz="0 0 0" rpy="0 0 ${M_PI}"/>
        <geometry name="${name}_arm_5_geom">
          <mesh filename="package://kuka_lwr_description/meshes/arm_segment_last.stl"/>
        </geometry>
        <material name="Orange"/>
      </visual>
    </link>


    <joint name="${name}_arm_5_joint" type="revolute">
      <origin xyz="0 0 0.19" rpy="0 0 0"/>
      <axis xyz="0 -1 0"/>
      <limit lower="${-120 * M_PI / 180}" upper="${120 * M_PI / 180}"
             effort="306" velocity="${arm_velocity_scale_factor * 180 * M_PI / 180}" />
      <parent link="${name}_arm_5_link"/>
      <child link="${name}_arm_6_link"/>
    </joint>

    <link name="${name}_arm_6_link">
      <visual>
        <origin xyz="0 0 0" rpy="0 0 ${M_PI}"/>
        <geometry>
          <mesh filename="package://kuka_lwr_description/meshes/arm_wrist.stl"/>
        </geometry>
        <material name="Grey"/>
      </visual>
    </link>

    <joint name="${name}_arm_6_joint" type="revolute">
      <origin xyz="0 0 0.078" rpy="0 0 0"/>
      <axis xyz="0 0 1"/>
      <limit lower="${-170 * M_PI / 180}" upper="${170 * M_PI / 180}"
             effort="204" velocity="${arm_velocity_scale_factor * 180 * M_PI / 180}" />
      <parent link="${name}_arm_6_link"/>
      <child link="${name}_arm_7_link"/>
    </joint>

    <link name="${name}_arm_7_link">
      <visual>
        <origin xyz="0 0 0" rpy="0 0 ${-1/4 * M_PI  +  M_PI}"/>
        <geometry>
          <mesh filename="package://kuka_lwr_description/meshes/arm_flanche.stl"/>
        </geometry>
        <material name="Grey"/>
      </visual>
    </link>
    
   <joint name="${name}_arm_flange_joint" type="fixed">
      <origin xyz="0 0 0" rpy="0 0 0"/>
      <parent link="${name}_arm_7_link"/>
      <child link="${name}_arm_flange_link"/>
   </joint>

   <link name="${name}_arm_flange_link">
   </link>

  </macro>

</robot>
